2025-02-24T02:06:43.6084236Z ##[group]Run python -m pytest tests/ --cov=src/ --cov-report=xml
2025-02-24T02:06:43.6084807Z [36;1mpython -m pytest tests/ --cov=src/ --cov-report=xml[0m
2025-02-24T02:06:43.6145194Z shell: /usr/bin/bash -e {0}
2025-02-24T02:06:43.6145529Z env:
2025-02-24T02:06:43.6145869Z   pythonLocation: /opt/hostedtoolcache/Python/3.9.21/x64
2025-02-24T02:06:43.6146454Z   PKG_CONFIG_PATH: /opt/hostedtoolcache/Python/3.9.21/x64/lib/pkgconfig
2025-02-24T02:06:43.6147020Z   Python_ROOT_DIR: /opt/hostedtoolcache/Python/3.9.21/x64
2025-02-24T02:06:43.6147526Z   Python2_ROOT_DIR: /opt/hostedtoolcache/Python/3.9.21/x64
2025-02-24T02:06:43.6148034Z   Python3_ROOT_DIR: /opt/hostedtoolcache/Python/3.9.21/x64
2025-02-24T02:06:43.6148551Z   LD_LIBRARY_PATH: /opt/hostedtoolcache/Python/3.9.21/x64/lib
2025-02-24T02:06:43.6148977Z ##[endgroup]
2025-02-24T02:06:44.1765333Z ============================= test session starts ==============================
2025-02-24T02:06:44.1766016Z platform linux -- Python 3.9.21, pytest-8.1.1, pluggy-1.5.0
2025-02-24T02:06:44.1766794Z rootdir: /home/runner/work/securityhub_soc2analysis/securityhub_soc2analysis
2025-02-24T02:06:44.1767378Z configfile: pytest.ini
2025-02-24T02:06:44.1767692Z plugins: cov-4.1.0
2025-02-24T02:06:44.1768015Z collected 0 items / 1 error
2025-02-24T02:06:44.1768221Z 
2025-02-24T02:06:44.1768390Z ==================================== ERRORS ====================================
2025-02-24T02:06:44.1768924Z _____________________ ERROR collecting tests/test_index.py _____________________
2025-02-24T02:06:44.1770106Z ImportError while importing test module '/home/runner/work/securityhub_soc2analysis/securityhub_soc2analysis/tests/test_index.py'.
2025-02-24T02:06:44.1771081Z Hint: make sure your test modules/packages have valid Python names.
2025-02-24T02:06:44.1771557Z Traceback:
2025-02-24T02:06:44.1772116Z /opt/hostedtoolcache/Python/3.9.21/x64/lib/python3.9/importlib/__init__.py:127: in import_module
2025-02-24T02:06:44.1772889Z     return _bootstrap._gcd_import(name[level:], package, level)
2025-02-24T02:06:44.1773377Z tests/test_index.py:14: in <module>
2025-02-24T02:06:44.1773862Z     from src.handlers.securityhub_handler import (generate_soc2_csv,
2025-02-24T02:06:44.1774424Z src/handlers/securityhub_handler.py:6: in <module>
2025-02-24T02:06:44.1775176Z     from datetime import datetime, timedelta, UTC
2025-02-24T02:06:44.1775970Z E   ImportError: cannot import name 'UTC' from 'datetime' (/opt/hostedtoolcache/Python/3.9.21/x64/lib/python3.9/datetime.py)
2025-02-24T02:06:44.1776603Z 
2025-02-24T02:06:44.1776860Z ---------- coverage: platform linux, python 3.9.21-final-0 -----------
2025-02-24T02:06:44.1777399Z Coverage XML written to file coverage.xml
2025-02-24T02:06:44.1777660Z 
2025-02-24T02:06:44.1777843Z =========================== short test summary info ============================
2025-02-24T02:06:44.1778296Z ERROR tests/test_index.py
2025-02-24T02:06:44.1778738Z !!!!!!!!!!!!!!!!!!!! Interrupted: 1 error during collection !!!!!!!!!!!!!!!!!!!!
2025-02-24T02:06:44.1779266Z =============================== 1 error in 0.21s ===============================
2025-02-24T02:06:44.2050271Z ##[error]Process completed with exit code 2.
